Workbook

Sheet Q1
B2: Risk free | C2: 0.004 | D2: Asset 1 return | E2: 0.015 | F2: Asset 2 return | G2: 0.008 | J2: V: | K2: =E3^2 -> 0.01 | L2: =I3 -> 0.002 | N2: V^-1: | O2: {=MINVERSE(K2:L3)} -> 119.04762 | P2: -95.238095 | R2: E(R): | S2: =E2 -> 0.015 | T2: 1 | U2: K: | V2: {=MMULT(TRANSPOSE(S2:S3),MMULT(_xlfn.ANCHORARRAY(O2),S2:S3))} -> 0.034404762 | W2: {=MMULT(TRANSPOSE(T2:T3),MMULT(_xlfn.ANCHORARRAY(O2),S2:S3))} -> 3.4047619 | Y2: E(RG) | Z2: SD(RG) | AA2: E(Rp*) | AB2: SD(Rp*) | AC2: Slope
B3: Cor | C3: 0.4 | D3: sd | E3: 0.1 | F3: sd | G3: 0.05 | H3: Cov | I3: =C3*E3*G3 -> 0.002 | K3: =I3 -> 0.002 | L3: =G3^2 -> 0.0025 | O3: -95.238095 | P3: 476.19048 | S3: =G2 -> 0.008 | T3: 1 | V3: {=MMULT(TRANSPOSE(T2:T3),MMULT(_xlfn.ANCHORARRAY(O2),T2:T3))} -> 404.7619 | W3: =V2*V3-W2^2 -> 2.3333333 | Y3: =W2/V3 -> 0.0084117647 | Z3: =SQRT(($V$3*Y3^2-2*$W$2*Y3+$V$2)/$W$3) -> 0.049705012 | AA3: =(C2*W2-V2)/(C2*V3-W2) -> 0.01164 | AB3: =SQRT(($V$3*AA3^2-2*$W$2*AA3+$V$2)/$W$3) -> 0.065409479 | AC3: =W3*AB3/(V3*AA3-W2) -> 0.11680264
B4: Proportion in Risky Asset 1 | C4: Proportion in Risky Asset 2 | D4: E(R) | E4: Var(R)^0.5 | F4: Capital Allocation Line
B5: -5 | C5: =1-B5 -> 6 | D5: =B5*$E$2+C5*$G$2 -> -0.027 | E5: =(B5^2*$E$3^2+C5^2*$G$3^2+2*B5*C5*$I$3)^0.5 -> 0.46904158 | F5: =$C$2+$AC$3*E5 -> 0.058785295
B6: -1.5 | C6: =1-B6 -> 2.5 | D6: =B6*$E$2+C6*$G$2 -> -0.0025 | E6: =(B6^2*$E$3^2+C6^2*$G$3^2+2*B6*C6*$I$3)^0.5 -> 0.15206906 | F6: =$C$2+$AC$3*E6 -> 0.021762068
B7: -0.8 | C7: =1-B7 -> 1.8 | D7: =B7*$E$2+C7*$G$2 -> 0.0024 | E7: =(B7^2*$E$3^2+C7^2*$G$3^2+2*B7*C7*$I$3)^0.5 -> 0.093487967 | F7: =$C$2+$AC$3*E7 -> 0.014919642
B8: -0.7 | C8: =1-B8 -> 1.7 | D8: =B8*$E$2+C8*$G$2 -> 0.0031 | E8: =(B8^2*$E$3^2+C8^2*$G$3^2+2*B8*C8*$I$3)^0.5 -> 0.085819578 | F8: =$C$2+$AC$3*E8 -> 0.014023953
B9: -0.6 | C9: =1-B9 -> 1.6 | D9: =B9*$E$2+C9*$G$2 -> 0.0038 | E9: =(B9^2*$E$3^2+C9^2*$G$3^2+2*B9*C9*$I$3)^0.5 -> 0.078485667 | F9: =$C$2+$AC$3*E9 -> 0.013167333
B10: -0.5 | C10: =1-B10 -> 1.5 | D10: =B10*$E$2+C10*$G$2 -> 0.0045 | E10: =(B10^2*$E$3^2+C10^2*$G$3^2+2*B10*C10*$I$3)^0.5 -> 0.071589105 | F10: =$C$2+$AC$3*E10 -> 0.012361797
B11: -0.4 | C11: =1-B11 -> 1.4 | D11: =B11*$E$2+C11*$G$2 -> 0.0052 | E11: =(B11^2*$E$3^2+C11^2*$G$3^2+2*B11*C11*$I$3)^0.5 -> 0.065268675 | F11: =$C$2+$AC$3*E11 -> 0.011623554
B12: -0.3 | C12: =1-B12 -> 1.3 | D12: =B12*$E$2+C12*$G$2 -> 0.0059 | E12: =(B12^2*$E$3^2+C12^2*$G$3^2+2*B12*C12*$I$3)^0.5 -> 0.059707621 | F12: =$C$2+$AC$3*E12 -> 0.010974008
B13: -0.2 | C13: =1-B13 -> 1.2 | D13: =B13*$E$2+C13*$G$2 -> 0.0066 | E13: =(B13^2*$E$3^2+C13^2*$G$3^2+2*B13*C13*$I$3)^0.5 -> 0.055136195 | F13: =$C$2+$AC$3*E13 -> 0.010440053
B14: -0.1 | C14: =1-B14 -> 1.1 | D14: =B14*$E$2+C14*$G$2 -> 0.0073 | E14: =(B14^2*$E$3^2+C14^2*$G$3^2+2*B14*C14*$I$3)^0.5 -> 0.051816986 | F14: =$C$2+$AC$3*E14 -> 0.010052361
B15: 9.9920072e-16 | C15: =1-B15 -> 1 | D15: =B15*$E$2+C15*$G$2 -> 0.008 | E15: =(B15^2*$E$3^2+C15^2*$G$3^2+2*B15*C15*$I$3)^0.5 -> 0.05 | F15: =$C$2+$AC$3*E15 -> 0.0098401321
B16: 0.1 | C16: =1-B16 -> 0.9 | D16: =B16*$E$2+C16*$G$2 -> 0.0087 | E16: =(B16^2*$E$3^2+C16^2*$G$3^2+2*B16*C16*$I$3)^0.5 -> 0.049849774 | F16: =$C$2+$AC$3*E16 -> 0.0098225853
... B29: 7.5 | C29: =1-B29 -> -6.5 | D29: =B29*$E$2+C29*$G$2 -> 0.0605 | E29: =(B29^2*$E$3^2+C29^2*$G$3^2+2*B29*C29*$I$3)^0.5 -> 0.68784082 | F29: =$C$2+$AC$3*E29 -> 0.084341625
E30: 0 | F30: =$C$2+$AC$3*E30 -> 0.004
B32: Risk free | C32: 0.004 | D32: Asset 1 return | E32: 0.015 | F32: Asset 2 return | G32: 0.008 | J32: V: | K32: =E33^2 -> 0.01 | L32: =I33 -> -0.005 | N32: V^-1: | O32: {=MINVERSE(K32:L33)} -> #NUM! | R32: E(R): | S32: =E32 -> 0.015 | T32: 1 | U32: K: | V32: {=MMULT(TRANSPOSE(S32:S33),MMULT(_xlfn.ANCHORARRAY(O32),S32:S33))} -> #NUM! | W32: {=MMULT(TRANSPOSE(T32:T33),MMULT(_xlfn.ANCHORARRAY(O32),S32:S33))} -> #NUM! | Y32: E(RG) | Z32: SD(RG) | AA32: E(Rp*) | AB32: SD(Rp*) | AC32: Slope
B33: Cor | C33: -1 | D33: sd | E33: 0.1 | F33: sd | G33: 0.05 | H33: Cov | I33: =C33*E33*G33 -> -0.005 | K33: =I33 -> -0.005 | L33: =G33^2 -> 0.0025 | S33: =G32 -> 0.008 | T33: 1 | V33: {=MMULT(TRANSPOSE(T32:T33),MMULT(_xlfn.ANCHORARRAY(O32),T32:T33))} -> #NUM! | W33: =V32*V33-W32^2 -> #NUM! | Y33: =W32/V33 -> #NUM! | Z33: =SQRT(($V$3*Y33^2-2*$W$2*Y33+$V$2)/$W$3) -> #NUM! | AA33: =(C32*W32-V32)/(C32*V33-W32) -> #NUM! | AB33: =SQRT(($V$3*AA33^2-2*$W$2*AA33+$V$2)/$W$3) -> #NUM! | AC33: =W33*AB33/(V33*AA33-W32) -> #NUM!
B34: Proportion in Risky Asset 1 | C34: Proportion in Risky Asset 2 | D34: E(R) | E34: Var(R)^0.5 | F34: Capital Allocation Line
B35: -5 | C35: =1-B35 -> 6 | D35: =B35*$E$2+C35*$G$2 -> -0.027 | E35: =(B35^2*$E$3^2+C35^2*$G$3^2+2*B35*C35*$I$33)^0.5 -> 0.8 | F35: =$C$2+$AC$33*E35 -> #NUM!
B36: -1.5 | C36: =1-B36 -> 2.5 | D36: =B36*$E$2+C36*$G$2 -> -0.0025 | E36: =(B36^2*$E$3^2+C36^2*$G$3^2+2*B36*C36*$I$33)^0.5 -> 0.275 | F36: =$C$2+$AC$33*E36 -> #NUM!
B37: -0.8 | C37: =1-B37 -> 1.8 | D37: =B37*$E$2+C37*$G$2 -> 0.0024 | E37: =(B37^2*$E$3^2+C37^2*$G$3^2+2*B37*C37*$I$33)^0.5 -> 0.17 | F37: =$C$2+$AC$33*E37 -> #NUM!
B38: -0.7 | C38: =1-B38 -> 1.7 | D38: =B38*$E$2+C38*$G$2 -> 0.0031 | E38: =(B38^2*$E$3^2+C38^2*$G$3^2+2*B38*C38*$I$33)^0.5 -> 0.155 | F38: =$C$2+$AC$33*E38 -> #NUM!
B39: -0.6 | C39: =1-B39 -> 1.6 | D39: =B39*$E$2+C39*$G$2 -> 0.0038 | E39: =(B39^2*$E$3^2+C39^2*$G$3^2+2*B39*C39*$I$33)^0.5 -> 0.14 | F39: =$C$2+$AC$33*E39 -> #NUM!
B40: -0.5 | C40: =1-B40 -> 1.5 | D40: =B40*$E$2+C40*$G$2 -> 0.0045 | E40: =(B40^2*$E$3^2+C40^2*$G$3^2+2*B40*C40*$I$33)^0.5 -> 0.125 | F40: =$C$2+$AC$33*E40 -> #NUM!
B41: -0.4 | C41: =1-B41 -> 1.4 | D41: =B41*$E$2+C41*$G$2 -> 0.0052 | E41: =(B41^2*$E$3^2+C41^2*$G$3^2+2*B41*C41*$I$33)^0.5 -> 0.11 | F41: =$C$2+$AC$33*E41 -> #NUM!
B42: -0.3 | C42: =1-B42 -> 1.3 | D42: =B42*$E$2+C42*$G$2 -> 0.0059 | E42: =(B42^2*$E$3^2+C42^2*$G$3^2+2*B42*C42*$I$33)^0.5 -> 0.095 | F42: =$C$2+$AC$33*E42 -> #NUM!
B43: -0.2 | C43: =1-B43 -> 1.2 | D43: =B43*$E$2+C43*$G$2 -> 0.0066 | E43: =(B43^2*$E$3^2+C43^2*$G$3^2+2*B43*C43*$I$33)^0.5 -> 0.08 | F43: =$C$2+$AC$33*E43 -> #NUM!
B44: -0.1 | C44: =1-B44 -> 1.1 | D44: =B44*$E$2+C44*$G$2 -> 0.0073 | E44: =(B44^2*$E$3^2+C44^2*$G$3^2+2*B44*C44*$I$33)^0.5 -> 0.065 | F44: =$C$2+$AC$33*E44 -> #NUM!
B45: 9.9920072e-16 | C45: =1-B45 -> 1 | D45: =B45*$E$2+C45*$G$2 -> 0.008 | E45: =(B45^2*$E$3^2+C45^2*$G$3^2+2*B45*C45*$I$33)^0.5 -> 0.05 | F45: =$C$2+$AC$33*E45 -> #NUM!
B46: 0.1 | C46: =1-B46 -> 0.9 | D46: =B46*$E$2+C46*$G$2 -> 0.0087 | E46: =(B46^2*$E$3^2+C46^2*$G$3^2+2*B46*C46*$I$33)^0.5 -> 0.035 | F46: =$C$2+$AC$33*E46 -> #NUM!
... B59: 7.5 | C59: =1-B59 -> -6.5 | D59: =B59*$E$2+C59*$G$2 -> 0.0605 | E59: =(B59^2*$E$3^2+C59^2*$G$3^2+2*B59*C59*$I$33)^0.5 -> 1.075 | F59: =$C$2+$AC$33*E59 -> #NUM!
E60: 0 | F60: =$C$2+$AC$33*E60 -> #NUM!
B62: Risk free | C62: 0.004 | D62: Asset 1 return | E62: 0.015 | F62: Asset 2 return | G62: 0.008 | J62: V: | K62: =E63^2 -> 0.01 | L62: =I63 -> 0 | N62: V^-1: | O62: {=MINVERSE(K62:L63)} -> 100 | P62: 0 | R62: E(R): | S62: =E62 -> 0.015 | T62: 1 | U62: K: | V62: {=MMULT(TRANSPOSE(S62:S63),MMULT(_xlfn.ANCHORARRAY(O62),S62:S63))} -> 0.0481 | W62: {=MMULT(TRANSPOSE(T62:T63),MMULT(_xlfn.ANCHORARRAY(O62),S62:S63))} -> 4.7 | Y62: E(RG) | Z62: SD(RG) | AA62: E(Rp*) | AB62: SD(Rp*) | AC62: Slope
B63: Cor | C63: 0 | D63: sd | E63: 0.1 | F63: sd | G63: 0.05 | H63: Cov | I63: =C63*E63*G63 -> 0 | K63: =I63 -> 0 | L63: =G63^2 -> 0.0025 | O63: 0 | P63: 400 | S63: =G62 -> 0.008 | T63: 1 | V63: {=MMULT(TRANSPOSE(T62:T63),MMULT(_xlfn.ANCHORARRAY(O62),T62:T63))} -> 500 | W63: =V62*V63-W62^2 -> 1.96 | Y63: =W62/V63 -> 0.0094 | Z63: =SQRT(($V$3*Y63^2-2*$W$2*Y63+$V$2)/$W$3) -> 0.05138093 | AA63: =(C62*W62-V62)/(C62*V63-W62) -> 0.010851852 | AB63: =SQRT(($V$3*AA63^2-2*$W$2*AA63+$V$2)/$W$3) -> 0.059189774 | AC63: =W63*AB63/(V63*AA63-W62) -> 0.15981239
B64: Proportion in Risky Asset 1 | C64: Proportion in Risky Asset 2 | D64: E(R) | E64: Var(R)^0.5 | F64: Capital Allocation Line
B65: -5 | C65: =1-B65 -> 6 | D65: =B65*$E$2+C65*$G$2 -> -0.027 | E65: =(B65^2*$E$3^2+C65^2*$G$3^2+2*B65*C65*$I$63)^0.5 -> 0.58309519 | F65: =$C$2+$AC$63*E65 -> 0.097185836
B66: -1.5 | C66: =1-B66 -> 2.5 | D66: =B66*$E$2+C66*$G$2 -> -0.0025 | E66: =(B66^2*$E$3^2+C66^2*$G$3^2+2*B66*C66*$I$63)^0.5 -> 0.19525624 | F66: =$C$2+$AC$63*E66 -> 0.035204367
B67: -0.8 | C67: =1-B67 -> 1.8 | D67: =B67*$E$2+C67*$G$2 -> 0.0024 | E67: =(B67^2*$E$3^2+C67^2*$G$3^2+2*B67*C67*$I$63)^0.5 -> 0.12041595 | F67: =$C$2+$AC$63*E67 -> 0.02324396
...

Sheet Q2->
B2: Please note that this Excel file has answers for both Questions 1 and 2. As the worksheet name shows, all worksheets to the right of this worksheet are for Question 2. Thank you :)

Sheet i
B1: =COMBIN(6,2) -> 15 | C1: Stock | D1: Stock | E1: Stock | F1: Stock | G1: Stock | H1: Stock | I1: US Portfolio | J1: US Portfolio | K1: US Portfolio | L1: US Portfolio | M1: US Portfolio | N1: US Portfolio | O1: Country Port | P1: Country Port | Q1: Country Port | R1: Country Port | S1: Country Port | T1: Country Port | U1: US Riskfree
B2: =B1*2+19 -> 49 | C2: Barrick | D2: Hanson | E2: IBM | F2: Nokia | G2: Telefonos | H2: YPF | I2: Small-Growth | J2: Small-Neutral | K2: Small-Value | L2: Big-Growth | M2: Big-Neutral | N2: Big-Value | O2: Australia | P2: Hong Kong | Q2: Italy | R2: Japan | S2: Norway | T2: US | U2: US Riskfree
B3: Covariances:
A5: {=TRANSPOSE(C1:U2)} -> Stock | B5: Barrick | C5: =_xlfn.COVARIANCE.S($C$55:$C$174,C$55:C$174) -> 0.010636096 | D5: =_xlfn.COVARIANCE.S($C55:$C174,D55:D174) -> 0.0027643188 | E5: =_xlfn.COVARIANCE.S($C55:$C174,E55:E174) -> 0.00075121642 | F5: =_xlfn.COVARIANCE.S($C55:$C174,F55:F174) -> 0.0016980916 | G5: =_xlfn.COVARIANCE.S($C55:$C174,G55:G174) -> 0.0022133436 | H5: =_xlfn.COVARIANCE.S($C55:$C174,H55:H174) -> 0.003035016 | I5: =_xlfn.COVARIANCE.S($C55:$C174,I55:I174) -> -0.0014364252 | J5: =_xlfn.COVARIANCE.S($C55:$C174,J55:J174) -> -0.0008711034 | K5: =_xlfn.COVARIANCE.S($C55:$C174,K55:K174) -> -0.00068893753 | ... U5: =_xlfn.COVARIANCE.S($C55:$C174,U55:U174) -> -8.120813e-06
A6: Stock | B6: Hanson | C6: =_xlfn.COVARIANCE.S($D$55:$D$174,C$55:C$174) -> 0.0027643188 | D6: =_xlfn.COVARIANCE.S($D$55:$D$174,D$55:D$174) -> 0.010000093 | E6: =_xlfn.COVARIANCE.S($D$55:$D$174,E$55:E$174) -> 0.0018747776 | F6: =_xlfn.COVARIANCE.S($D$55:$D$174,F$55:F$174) -> 0.0027808038 | G6: =_xlfn.COVARIANCE.S($D$55:$D$174,G$55:G$174) -> 0.0017497179 | H6: =_xlfn.COVARIANCE.S($D$55:$D$174,H$55:H$174) -> 0.0023641431 | I6: =_xlfn.COVARIANCE.S($D$55:$D$174,I$55:I$174) -> -0.00085327127 | J6: =_xlfn.COVARIANCE.S($D$55:$D$174,J$55:J$174) -> -0.00041298732 | ... U6: =_xlfn.COVARIANCE.S($D$55:$D$174,U$55:U$174) -> -4.5252366e-06
A7: Stock | B7: IBM | C7: =_xlfn.COVARIANCE.S($E$55:$E$174,C$55:C$174) -> 0.00075121642 | D7: =_xlfn.COVARIANCE.S($E$55:$E$174,D$55:D$174) -> 0.0018747776 | E7: =_xlfn.COVARIANCE.S($E$55:$E$174,E$55:E$174) -> 0.0088172672 | F7: =_xlfn.COVARIANCE.S($E$55:$E$174,F$55:F$174) -> 0.0053882443 | G7: =_xlfn.COVARIANCE.S($E$55:$E$174,G$55:G$174) -> 0.003284448 | H7: =_xlfn.COVARIANCE.S($E$55:$E$174,H$55:H$174) -> 0.0030329717 | I7: =_xlfn.COVARIANCE.S($E$55:$E$174,I$55:I$174) -> -0.00012212334 | J7: =_xlfn.COVARIANCE.S($E$55:$E$174,J$55:J$174) -> -0.00016631146 | ... U7: =_xlfn.COVARIANCE.S($E$55:$E$174,U$55:U$174) -> 1.2770504e-05
A8: Stock | B8: Nokia | C8: =_xlfn.COVARIANCE.S($F$55:$F$174,C$55:C$174) -> 0.0016980916 | D8: =_xlfn.COVARIANCE.S($F$55:$F$174,D$55:D$174) -> 0.0027808038 | E8: =_xlfn.COVARIANCE.S($F$55:$F$174,E$55:E$174) -> 0.0053882443 | F8: =_xlfn.COVARIANCE.S($F$55:$F$174,F$55:F$174) -> 0.018871172 | G8: =_xlfn.COVARIANCE.S($F$55:$F$174,G$55:G$174) -> 0.0046522898 | H8: =_xlfn.COVARIANCE.S($F$55:$F$174,H$55:H$174) -> 0.0028931109 | I8: =_xlfn.COVARIANCE.S($F$55:$F$174,I$55:I$174) -> -0.00097753045 | J8: =_xlfn.COVARIANCE.S($F$55:$F$174,J$55:J$174) -> -0.001166296 | ... U8: =_xlfn.COVARIANCE.S($F$55:$F$174,U$55:U$174) -> 1.4487359e-05
A9: Stock | B9: Telefonos | C9: =_xlfn.COVARIANCE.S($G$55:$G$174,C$55:C$174) -> 0.0022133436 | D9: =_xlfn.COVARIANCE.S($G$55:$G$174,D$55:D$174) -> 0.0017497179 | E9: =_xlfn.COVARIANCE.S($G$55:$G$174,E$55:E$174) -> 0.003284448 | F9: =_xlfn.COVARIANCE.S($G$55:$G$174,F$55:F$174) -> 0.0046522898 | G9: =_xlfn.COVARIANCE.S($G$55:$G$174,G$55:G$174) -> 0.008254405 | H9: =_xlfn.COVARIANCE.S($G$55:$G$174,H$55:H$174) -> 0.003632472 | I9: =_xlfn.COVARIANCE.S($G$55:$G$174,I$55:I$174) -> -7.452494e-06 | J9: =_xlfn.COVARIANCE.S($G$55:$G$174,J$55:J$174) -> -0.00031954435 | ... U9: =_xlfn.COVARIANCE.S($G$55:$G$174,U$55:U$174) -> 1.2615467e-05
A10: Stock | B10: YPF | C10: =_xlfn.COVARIANCE.S($H$55:$H$174,C$55:C$174) -> 0.003035016 | D10: =_xlfn.COVARIANCE.S($H$55:$H$174,D$55:D$174) -> 0.0023641431 | E10: =_xlfn.COVARIANCE.S($H$55:$H$174,E$55:E$174) -> 0.0030329717 | F10: =_xlfn.COVARIANCE.S($H$55:$H$174,F$55:F$174) -> 0.0028931109 | G10: =_xlfn.COVARIANCE.S($H$55:$H$174,G$55:G$174) -> 0.003632472 | H10: =_xlfn.COVARIANCE.S($H$55:$H$174,H$55:H$174) -> 0.010684864 | I10: =_xlfn.COVARIANCE.S($H$55:$H$174,I$55:I$174) -> 6.1267511e-05 | J10: =_xlfn.COVARIANCE.S($H$55:$H$174,J$55:J$174) -> -0.00040788001 | ... U10: =_xlfn.COVARIANCE.S($H$55:$H$174,U$55:U$174) -> -2.7764349e-05
A11: US Portfolio | B11: Small-Growth | C11: =_xlfn.COVARIANCE.S($I$55:$I$174,C$55:C$174) -> -0.0014364252 | D11: =_xlfn.COVARIANCE.S($I$55:$I$174,D$55:D$174) -> -0.00085327127 | E11: =_xlfn.COVARIANCE.S($I$55:$I$174,E$55:E$174) -> -0.00012212334 | F11: =_xlfn.COVARIANCE.S($I$55:$I$174,F$55:F$174) -> -0.00097753045 | G11: =_xlfn.COVARIANCE.S($I$55:$I$174,G$55:G$174) -> -7.452494e-06 | H11: =_xlfn.COVARIANCE.S($I$55:$I$174,H$55:H$174) -> 6.1267511e-05 | I11: =_xlfn.COVARIANCE.S($I$55:$I$174,I$55:I$174) -> 0.0064521217 | J11: =_xlfn.COVARIANCE.S($I$55:$I$174,J$55:J$174) -> 0.0038269745 | ... U11: =_xlfn.COVARIANCE.S($I$55:$I$174,U$55:U$174) -> -6.4553908e-06
A12: US Portfolio | B12: Small-Neutral | C12: =_xlfn.COVARIANCE.S($J$55:$J$174,C$55:C$174) -> -0.0008711034 | D12: =_xlfn.COVARIANCE.S($J$55:$J$174,D$55:D$174) -> -0.00041298732 | E12: =_xlfn.COVARIANCE.S($J$55:$J$174,E$55:E$174) -> -0.00016631146 | F12: =_xlfn.COVARIANCE.S($J$55:$J$174,F$55:F$174) -> -0.001166296 | G12: =_xlfn.COVARIANCE.S($J$55:$J$174,G$55:G$174) -> -0.00031954435 | H12: =_xlfn.COVARIANCE.S($J$55:$J$174,H$55:H$174) -> -0.00040788001 | I12: =_xlfn.COVARIANCE.S($J$55:$J$174,I$55:I$174) -> 0.0038269745 | J12: =_xlfn.COVARIANCE.S($J$55:$J$174,J$55:J$174) -> 0.0027248232 | ... U12: =_xlfn.COVARIANCE.S($J$55:$J$174,U$55:U$174) -> -2.2595084e-06
A13: US Portfolio | B13: Small-Value | C13: =_xlfn.COVARIANCE.S($K$55:$K$174,C$55:C$174) -> -0.00068893753 | D13: =_xlfn.COVARIANCE.S($K$55:$K$174,D$55:D$174) -> -0.00041285539 | E13: =_xlfn.COVARIANCE.S($K$55:$K$174,E$55:E$174) -> -0.00037399162 | F13: =_xlfn.COVARIANCE.S($K$55:$K$174,F$55:F$174) -> -0.0015805277 | G13: =_xlfn.COVARIANCE.S($K$55:$K$174,G$55:G$174) -> -0.00054452837 | H13: =_xlfn.COVARIANCE.S($K$55:$K$174,H$55:H$174) -> -0.00066699543 | I13: =_xlfn.COVARIANCE.S($K$55:$K$174,I$55:I$174) -> 0.0033933552 | J13: =_xlfn.COVARIANCE.S($K$55:$K$174,J$55:J$174) -> 0.0025302356 | ... U13: =_xlfn.COVARIANCE.S($K$55:$K$174,U$55:U$174) -> -4.3168487e-06
A14: US Portfolio | B14: Big-Growth | C14: =_xlfn.COVARIANCE.S($L$55:$L$174,C$55:C$174) -> -0.00051716715 | D14: =_xlfn.COVARIANCE.S($L$55:$L$174,D$55:D$174) -> -0.0003804641 | E14: =_xlfn.COVARIANCE.S($L$55:$L$174,E$55:E$174) -> -0.00030320935 | F14: =_xlfn.COVARIANCE.S($L$55:$L$174,F$55:F$174) -> -0.00061687321 | G14: =_xlfn.COVARIANCE.S($L$55:$L$174,G$55:G$174) -> -0.00031862307 | H14: =_xlfn.COVARIANCE.S($L$55:$L$174,H$55:H$174) -> 0.00047215543 | I14: =_xlfn.COVARIANCE.S($L$55:$L$174,I$55:I$174) -> 0.0028034937 | J14: =_xlfn.COVARIANCE.S($L$55:$L$174,J$55:J$174) -> 0.0016614861 | ... U14: =_xlfn.COVARIANCE.S($L$55:$L$174,U$55:U$174) -> 2.3567311e-06
A15: US Portfolio | B15: Big-Neutral | C15: =_xlfn.COVARIANCE.S($M$55:$M$174,C$55:C$174) -> -0.00043084869 | D15: =_xlfn.COVARIANCE.S($M$55:$M$174,D$55:D$174) -> -0.00031747274 | E15: =_xlfn.COVARIANCE.S($M$55:$M$174,E$55:E$174) -> -0.00028047067 | F15: =_xlfn.COVARIANCE.S($M$55:$M$174,F$55:F$174) -> -0.0011781403 | G15: =_xlfn.COVARIANCE.S($M$55:$M$174,G$55:G$174) -> -0.00051756534 | H15: =_xlfn.COVARIANCE.S($M$55:$M$174,H$55:H$174) -> -0.0001296924 | I15: =_xlfn.COVARIANCE.S($M$55:$M$174,I$55:I$174) -> 0.0018398187 | J15: =_xlfn.COVARIANCE.S($M$55:$M$174,J$55:J$174) -> 0.0015593235 | ... U15: =_xlfn.COVARIANCE.S($M$55:$M$174,U$55:U$174) -> 3.5654916e-06
A16: US Portfolio | B16: Big-Value | C16: =_xlfn.COVARIANCE.S($N$55:$N$174,C$55:C$174) -> -0.00016217767 | D16: =_xlfn.COVARIANCE.S($N$55:$N$174,D$55:D$174) -> -0.00020981785 | E16: =_xlfn.COVARIANCE.S($N$55:$N$174,E$55:E$174) -> -0.0004928579 | F16: =_xlfn.COVARIANCE.S($N$55:$N$174,F$55:F$174) -> -0.00079417602 | G16: =_xlfn.COVARIANCE.S($N$55:$N$174,G$55:G$174) -> -0.00041682988 | H16: =_xlfn.COVARIANCE.S($N$55:$N$174,H$55:H$174) -> -7.5575813e-05 | I16: =_xlfn.COVARIANCE.S($N$55:$N$174,I$55:I$174) -> 0.0014590809 | J16: =_xlfn.COVARIANCE.S($N$55:$N$174,J$55:J$174) -> 0.0013465364 | ... U16: =_xlfn.COVARIANCE.S($N$55:$N$174,U$55:U$174) -> 4.8903361e-06
A17: Country Port | B17: Australia | C17: =_xlfn.COVARIANCE.S($O$55:$O$174,C$55:C$174) -> -0.00088886937 | D17: =_xlfn.COVARIANCE.S($O$55:$O$174,D$55:D$174) -> 0.00026003373 | E17: =_xlfn.COVARIANCE.S($O$55:$O$174,E$55:E$174) -> -0.0003801092 | F17: =_xlfn.COVARIANCE.S($O$55:$O$174,F$55:F$174) -> -0.0010324777 | G17: =_xlfn.COVARIANCE.S($O$55:$O$174,G$55:G$174) -> -0.00066889768 | H17: =_xlfn.COVARIANCE.S($O$55:$O$174,H$55:H$174) -> 0.0001093825 | I17: =_xlfn.COVARIANCE.S($O$55:$O$174,I$55:I$174) -> 0.0024402018 | J17: =_xlfn.COVARIANCE.S($O$55:$O$174,J$55:J$174) -> 0.0016072925 | ... U17: =_xlfn.COVARIANCE.S($O$55:$O$174,U$55:U$174) -> -1.2027853e-05
A18: Country Port | B18: Hong Kong | C18: =_xlfn.COVARIANCE.S($P$55:$P$174,C$55:C$174) -> 0.00028854215 | D18: =_xlfn.COVARIANCE.S($P$55:$P$174,D$55:D$174) -> 0.00042682081 | E18: =_xlfn.COVARIANCE.S($P$55:$P$174,E$55:E$174) -> 0.00046429049 | F18: =_xlfn.COVARIANCE.S($P$55:$P$174,F$55:F$174) -> -0.0014112806 | G18: =_xlfn.COVARIANCE.S($P$55:$P$174,G$55:G$174) -> -0.00017253468 | H18: =_xlfn.COVARIANCE.S($P$55:$P$174,H$55:H$174) -> 0.00046944755 | I18: =_xlfn.COVARIANCE.S($P$55:$P$174,I$55:I$174) -> 0.0032209575 | J18: =_xlfn.COVARIANCE.S($P$55:$P$174,J$55:J$174) -> 0.0023338759 | ... U18: =_xlfn.COVARIANCE.S($P$55:$P$174,U$55:U$174) -> -7.5443487e-06
A19: Country Port | B19: Italy | C19: =_xlfn.COVARIANCE.S($Q$55:$Q$174,C$55:C$174) -> -0.00019132271 | D19: =_xlfn.COVARIANCE.S($Q$55:$Q$174,D$55:D$174) -> -0.00052870508 | E19: =_xlfn.COVARIANCE.S($Q$55:$Q$174,E$55:E$174) -> -0.00067532401 | F19: =_xlfn.COVARIANCE.S($Q$55:$Q$174,F$55:F$174) -> -0.00072140308 | G19: =_xlfn.COVARIANCE.S($Q$55:$Q$174,G$55:G$174) -> -0.0010646474 | H19: =_xlfn.COVARIANCE.S($Q$55:$Q$174,H$55:H$174) -> 0.00017386809 | I19: =_xlfn.COVARIANCE.S($Q$55:$Q$174,I$55:I$174) -> 0.0030591358 | J19: =_xlfn.COVARIANCE.S($Q$55:$Q$174,J$55:J$174) -> 0.0018669556 | ... U19: =_xlfn.COVARIANCE.S($Q$55:$Q$174,U$55:U$174) -> -4.2354622e-07
A20: Country Port | B20: Japan | C20: =_xlfn.COVARIANCE.S($R$55:$R$174,C$55:C$174) -> -0.0011172429 | D20: =_xlfn.COVARIANCE.S($R$55:$R$174,D$55:D$174) -> 0.00068391822 | E20: =_xlfn.COVARIANCE.S($R$55:$R$174,E$55:E$174) -> -0.0004214222 | F20: =_xlfn.COVARIANCE.S($R$55:$R$174,F$55:F$174) -> -0.0002983091 | G20: =_xlfn.COVARIANCE.S($R$55:$R$174,G$55:G$174) -> -0.00066771125 | H20: =_xlfn.COVARIANCE.S($R$55:$R$174,H$55:H$174) -> 0.00011682618 | I20: =_xlfn.COVARIANCE.S($R$55:$R$174,I$55:I$174) -> 0.0018911697 | J20: =_xlfn.COVARIANCE.S($R$55:$R$174,J$55:J$174) -> 0.0010566868 | ... U20: =_xlfn.COVARIANCE.S($R$55:$R$174,U$55:U$174) -> -1.0525345e-05
A21: Country Port | B21: Norway | C21: =_xlfn.COVARIANCE.S($S$55:$S$174,C$55:C$174) -> -0.0010389594 | D21: =_xlfn.COVARIANCE.S($S$55:$S$174,D$55:D$174) -> -0.00075823929 | E21: =_xlfn.COVARIANCE.S($S$55:$S$174,E$55:E$174) -> -0.00084727956 | F21: =_xlfn.COVARIANCE.S($S$55:$S$174,F$55:F$174) -> -0.0024846463 | G21: =_xlfn.COVARIANCE.S($S$55:$S$174,G$55:G$174) -> -0.0014278359 | H21: =_xlfn.COVARIANCE.S($S$55:$S$174,H$55:H$174) -> -0.00062787912 | I21: =_xlfn.COVARIANCE.S($S$55:$S$174,I$55:I$174) -> 0.0031511524 | J21: =_xlfn.COVARIANCE.S($S$55:$S$174,J$55:J$174) -> 0.0023080069 | ... U21: =_xlfn.COVARIANCE.S($S$55:$S$174,U$55:U$174) -> -1.3733084e-05
A22: Country Port | B22: US | C22: =_xlfn.COVARIANCE.S($T$55:$T$174,C$55:C$174) -> -0.00063728985 | D22: =_xlfn.COVARIANCE.S($T$55:$T$174,D$55:D$174) -> -0.00042250504 | E22: =_xlfn.COVARIANCE.S($T$55:$T$174,E$55:E$174) -> -0.00026893747 | F22: =_xlfn.COVARIANCE.S($T$55:$T$174,F$55:F$174) -> -0.0008525204 | G22: =_xlfn.COVARIANCE.S($T$55:$T$174,G$55:G$174) -> -0.00034691286 | H22: =_xlfn.COVARIANCE.S($T$55:$T$174,H$55:H$174) -> 0.00025035041 | I22: =_xlfn.COVARIANCE.S($T$55:$T$174,I$55:I$174) -> 0.0029969937 | J22: =_xlfn.COVARIANCE.S($T$55:$T$174,J$55:J$174) -> 0.0018872436 | ... U22: =_xlfn.COVARIANCE.S($T$55:$T$174,U$55:U$174) -> -3.8012605e-08
A23: US Riskfree | B23: US Riskfree | C23: =_xlfn.COVARIANCE.S($U$55:$U$174,C$55:C$174) -> -8.120813e-06 | D23: =_xlfn.COVARIANCE.S($U$55:$U$174,D$55:D$174) -> -4.5252366e-06 | E23: =_xlfn.COVARIANCE.S($U$55:$U$174,E$55:E$174) -> 1.2770504e-05 | F23: =_xlfn.COVARIANCE.S($U$55:$U$174,F$55:F$174) -> 1.4487359e-05 | G23: =_xlfn.COVARIANCE.S($U$55:$U$174,G$55:G$174) -> 1.2615467e-05 | H23: =_xlfn.COVARIANCE.S($U$55:$U$174,H$55:H$174) -> -2.7764349e-05 | I23: =_xlfn.COVARIANCE.S($U$55:$U$174,I$55:I$174) -> -6.4553908e-06 | J23: =_xlfn.COVARIANCE.S($U$55:$U$174,J$55:J$174) -> -2.2595084e-06 | ... U23: =_xlfn.COVARIANCE.S($U$55:$U$174,U$55:U$174) -> 2.132916e-06
C25: Stock | D25: Stock | E25: Stock | F25: Stock | G25: Stock | H25: Stock | I25: US Portfolio | J25: US Portfolio | K25: US Portfolio | L25: US Portfolio | M25: US Portfolio | N25: US Portfolio | O25: Country Port | P25: Country Port | Q25: Country Port | R25: Country Port | S25: Country Port | T25: Country Port | U25: US Riskfree
C26: Barrick | D26: Hanson | E26: IBM | F26: Nokia | G26: Telefonos | H26: YPF | I26: Small-Growth | J26: Small-Neutral | K26: Small-Value | L26: Big-Growth | M26: Big-Neutral | N26: Big-Value | O26: Australia | P26: Hong Kong | Q26: Italy | R26: Japan | S26: Norway | T26: US | U26: US Riskfree
B27: Correlations:
A29: {=TRANSPOSE(C25:U26)} -> Stock | B29: Barrick | C29: =C5/$C$50/C$50 -> 1 | D29: =D5/$C$50/D$50 -> 0.26803715 | E29: =E5/$C$50/E$50 -> 0.07757235 | F29: =F5/$C$50/F$50 -> 0.11985898 | G29: =G5/$C$50/G$50 -> 0.236219 | H29: =H5/$C$50/H$50 -> 0.28469862 | I29: =I5/$C$50/I$50 -> -0.17339661 | J29: =J5/$C$50/J$50 -> -0.16181152 | ... U29: =U5/$C$50/U$50 -> -0.053916478
A30: Stock | B30: Hanson | C30: =C6/$D$50/C$50 -> 0.26803715 | D30: =D6/$D$50/D$50 -> 1 | E30: =E6/$D$50/E$50 -> 0.19965525 | F30: =F6/$D$50/F$50 -> 0.20242722 | G30: =G6/$D$50/G$50 -> 0.1925853 | H30: =H6/$D$50/H$50 -> 0.2287111 | I30: =I6/$D$50/I$50 -> -0.10622673 | J30: =J6/$D$50/J$50 -> -0.079116221 | ... U30: =U6/$D$50/U$50 -> -0.030985064
A31: Stock | B31: IBM | C31: =C7/$E$50/C$50 -> 0.07757235 | D31: =D7/$E$50/D$50 -> 0.19965525 | E31: =E7/$E$50/E$50 -> 1 | F31: =F7/$E$50/F$50 -> 0.41771574 | G31: =G7/$E$50/G$50 -> 0.38499271 | H31: =H7/$E$50/H$50 -> 0.31247614 | I31: =I7/$E$50/I$50 -> -0.016191251 | J31: =J7/$E$50/J$50 -> -0.033930168 | ... U31: =U7/$E$50/U$50 -> 0.093122398
A32: Stock | B32: Nokia | C32: =C8/$F$50/C$50 -> 0.11985898 | D32: =D8/$F$50/D$50 -> 0.20242722 | E32: =E8/$F$50/E$50 -> 0.41771574 | F32: =F8/$F$50/F$50 -> 1 | G32: =G8/$F$50/G$50 -> 0.37275582 | H32: =H8/$F$50/H$50 -> 0.20374227 | I32: =I8/$F$50/I$50 -> -0.088588956 | J32: =J8/$F$50/J$50 -> -0.1626448 | ... U32: =U8/$F$50/U$50 -> 0.072210924
A33: Stock | B33: Telefonos | C33: =C9/$G$50/C$50 -> 0.236219 | D33: =D9/$G$50/D$50 -> 0.1925853 | E33: =E9/$G$50/E$50 -> 0.38499271 | F33: =F9/$G$50/F$50 -> 0.37275582 | G33: =G9/$G$50/G$50 -> 1 | H33: =H9/$G$50/H$50 -> 0.38678969 | I33: =I9/$G$50/I$50 -> -0.0010211922 | J33: =J9/$G$50/J$50 -> -0.067378151 | ... U33: =U9/$G$50/U$50 -> 0.095076585
A34: Stock | B34: YPF | C34: =C10/$H$50/C$50 -> 0.28469862 | D34: =D10/$H$50/D$50 -> 0.2287111 | E34: =E10/$H$50/E$50 -> 0.31247614 | F34: =F10/$H$50/F$50 -> 0.20374227 | G34: =G10/$H$50/G$50 -> 0.38678969 | H34: =H10/$H$50/H$50 -> 1 | I34: =I10/$H$50/I$50 -> 0.0073789483 | J34: =J10/$H$50/J$50 -> -0.07559251 | ... U34: =U10/$H$50/U$50 -> -0.18391456
A35: US Portfolio | B35: Small-Growth | C35: =C11/$I$50/C$50 -> -0.17339661 | D35: =D11/$I$50/D$50 -> -0.10622673 | E35: =E11/$I$50/E$50 -> -0.016191251 | F35: =F11/$I$50/F$50 -> -0.088588956 | G35: =G11/$I$50/G$50 -> -0.0010211922 | H35: =H11/$I$50/H$50 -> 0.0073789483 | I35: =I11/$I$50/I$50 -> 1 | J35: =J11/$I$50/J$50 -> 0.91271488 | ... U35: =U11/$I$50/U$50 -> -0.055028083
A36: US Portfolio | B36: Small-Neutral | C36: =C12/$J$50/C$50 -> -0.16181152 | D36: =D12/$J$50/D$50 -> -0.079116221 | E36: =E12/$J$50/E$50 -> -0.033930168 | F36: =F12/$J$50/F$50 -> -0.1626448 | G36: =G12/$J$50/G$50 -> -0.067378151 | H36: =H12/$J$50/H$50 -> -0.07559251 | I36: =I12/$J$50/I$50 -> 0.91271488 | J36: =J12/$J$50/J$50 -> 1 | ... U36: =U12/$J$50/U$50 -> -0.029638616
A37: US Portfolio | B37: Small-Value | C37: =C13/$K$50/C$50 -> -0.13289252 | D37: =D13/$K$50/D$50 -> -0.082131122 | E37: =E13/$K$50/E$50 -> -0.079233105 | F37: =F13/$K$50/F$50 -> -0.2288835 | G37: =G13/$K$50/G$50 -> -0.11923107 | H37: =H13/$K$50/H$50 -> -0.12836605 | I37: =I13/$K$50/I$50 -> 0.84040737 | J37: =J13/$K$50/J$50 -> 0.96428101 | ... U37: =U13/$K$50/U$50 -> -0.058801956
A38: US Portfolio | B38: Big-Growth | C38: =C14/$L$50/C$50 -> -0.10388195 | D38: =D14/$L$50/D$50 -> -0.078815554 | E38: =E14/$L$50/E$50 -> -0.066892259 | F38: =F14/$L$50/F$50 -> -0.093024371 | G38: =G14/$L$50/G$50 -> -0.072649831 | H38: =H14/$L$50/H$50 -> 0.094623882 | I38: =I14/$L$50/I$50 -> 0.72301711 | J38: =J14/$L$50/J$50 -> 0.65936791 | ... U38: =U14/$L$50/U$50 -> 0.033429003
A39: US Portfolio | B39: Big-Neutral | C39: =C15/$M$50/C$50 -> -0.095710578 | D39: =D15/$M$50/D$50 -> -0.072732867 | E39: =E15/$M$50/E$50 -> -0.068430031 | F39: =F15/$M$50/F$50 -> -0.19648249 | G39: =G15/$M$50/G$50 -> -0.13051144 | H39: =H15/$M$50/H$50 -> -0.028744602 | I39: =I15/$M$50/I$50 -> 0.52474709 | J39: =J15/$M$50/J$50 -> 0.68437376 | ... U39: =U15/$M$50/U$50 -> 0.055931804
A40: US Portfolio | B40: Big-Value | C40: =C16/$N$50/C$50 -> -0.035809851 | D40: =D16/$N$50/D$50 -> -0.047779651 | E40: =E16/$N$50/E$50 -> -0.1195246 | F40: =F16/$N$50/F$50 -> -0.13164971 | G40: =G16/$N$50/G$50 -> -0.10447648 | H40: =H16/$N$50/H$50 -> -0.016649489 | I40: =I16/$N$50/I$50 -> 0.41364774 | J40: =J16/$N$50/J$50 -> 0.58742375 | ... U40: =U16/$N$50/U$50 -> 0.076252556
A41: Country Port | B41: Australia | C41: =C17/$O$50/C$50 -> -0.17222918 | D41: =D17/$O$50/D$50 -> 0.051962206 | E41: =E17/$O$50/E$50 -> -0.0808912 | F41: =F17/$O$50/F$50 -> -0.15019005 | G41: =G17/$O$50/G$50 -> -0.14712169 | H41: =H17/$O$50/H$50 -> 0.021145759 | I41: =I17/$O$50/I$50 -> 0.60706385 | J41: =J17/$O$50/J$50 -> 0.61529824 | ... U41: =U17/$O$50/U$50 -> -0.16457397
A42: Country Port | B42: Hong Kong | C42: =C18/$P$50/C$50 -> 0.035713463 | D42: =D18/$P$50/D$50 -> 0.054482546 | E42: =E18/$P$50/E$50 -> 0.063115585 | F42: =F18/$P$50/F$50 -> -0.13113776 | G42: =G18/$P$50/G$50 -> -0.024240821 | H42: =H18/$P$50/H$50 -> 0.057971749 | I42: =I18/$P$50/I$50 -> 0.51185569 | J42: =J18/$P$50/J$50 -> 0.57071911 | ... U42: =U18/$P$50/U$50 -> -0.065939964
A43: Country Port | B43: Italy | C43: =C19/$Q$50/C$50 -> -0.02929883 | D43: =D19/$Q$50/D$50 -> -0.083499975 | E43: =E19/$Q$50/E$50 -> -0.11358476 | F43: =F19/$Q$50/F$50 -> -0.082937975 | G43: =G19/$Q$50/G$50 -> -0.18507075 | H43: =H19/$Q$50/H$50 -> 0.026565027 | I43: =I19/$Q$50/I$50 -> 0.60148162 | J43: =J19/$Q$50/J$50 -> 0.56485854 | ... U43: =U19/$Q$50/U$50 -> -0.0045802461
...

Sheet ii
A1: V: | B1: {=i!O17:T22} -> 0.0025042645 | C1: 0.002390442 | D1: 0.0015460553 | E1: 0.0016855515 | F1: 0.0022106706 | G1: 0.0015686001 | I1: V^-1: | J1: {=MINVERSE(_xlfn.ANCHORARRAY(B1))} -> 1081.7055 | K1: -144.37771 | L1: -72.115901 | M1: -219.02291 | N1: -210.61287 | O1: -266.15124
B2: 0.002390442 | C2: 0.0061372294 | D2: 0.0015154608 | E2: 0.0021542569 | F2: 0.0025858945 | G2: 0.0021564129 | J2: -144.37771 | K2: 301.66134 | L2: 55.258628 | M2: -45.068119 | N2: -31.779875 | O2: -190.46115
B3: 0.0015460553 | C3: 0.0015154608 | D3: 0.004009131 | E3: 0.00085191114 | F3: 0.0023767914 | G3: 0.001793284 | J3: -72.115901 | K3: 55.258628 | L3: 455.21172 | M3: 61.514998 | N3: -119.71855 | O3: -315.12569
B4: 0.0016855515 | C4: 0.0021542569 | D4: 0.00085191114 | E4: 0.0034913815 | F4: 0.0016375593 | G4: 0.001282067 | J4: -219.02291 | K4: -45.068119 | L4: 61.514998 | M4: 450.3451 | N4: -19.676459 | O4: -98.47205
B5: 0.0022106706 | C5: 0.0025858945 | D5: 0.0023767914 | E5: 0.0016375593 | F5: 0.0045933206 | G5: 0.0019555389 | J5: -210.61287 | K5: -31.779875 | L5: -119.71855 | M5: -19.676459 | N5: 457.29638 | O5: -120.66568
B6: 0.0015686001 | C6: 0.0021564129 | D6: 0.001793284 | E6: 0.001282067 | F6: 0.0019555389 | G6: 0.0021169819 | J6: -266.15124 | K6: -190.46115 | L6: -315.12569 | M6: -98.47205 | N6: -120.66568 | O6: 1301.6275
A8: E(R) | B8: {=TRANSPOSE(_xlfn.ANCHORARRAY(J8))} -> 0.011499167 | I8: t(E(R) | J8: {=i!O49:T49} -> 0.011499167 | K8: 0.0079208333 | L8: 0.01362 | M8: 0.0041933333 | N8: 0.013995 | O8: 0.0081808333
B9: 0.0079208333
B10: 0.01362
B11: 0.0041933333
B12: 0.013995
B13: 0.0081808333
A15: 1 | B15: {=TRANSPOSE(J15:O15)} -> 1 | I15: 1 | J15: 1 | K15: 1 | L15: 1 | M15: 1 | N15: 1 | O15: 1
B16: 1
B17: 1
B18: 1
B19: 1
B20: 1
A22: A | B22: {=MMULT(_xlfn.ANCHORARRAY(J8),MMULT(_xlfn.ANCHORARRAY(J1),_xlfn.ANCHORARRAY(B8)))} -> 0.074793082
A23: B | B23: {=MMULT(J15:O15,MMULT(_xlfn.ANCHORARRAY(J1),_xlfn.ANCHORARRAY(B8)))} -> 4.8538655
A24: C | B24: {=MMULT(J15:O15,MMULT(_xlfn.ANCHORARRAY(J1),_xlfn.ANCHORARRAY(B15)))} -> 574.89835
A25: D | B25: =B22*B24-B23^2 -> 19.438409
A27: Equation:
A32: Solving for E(Rp):
A37: E(Rp)- just refers to | J37: and E(Rp)+:
A43: E(Rp)- | B43: E(Rp)+ | C43: Var(Rp)^0.5 | M43: Since the graph has the standard deviation as the x-axis, the label on the graph to the left is in the order of (σ(Rp),E(Rp)). In this way, I hope the label on the graph that says (0.04170657,0.008442998) suffices for the prompt in ii b) to show the global minimum variance portfolio expected return and standard deviation on the graph in (a). Just to make sure, the variance is 0.041707^2, which is equal to 0.001739.
A44: =B23/B24 -> 0.0084429978 | B44: =B23/B24 -> 0.0084429978 | C44: =SQRT((B24*B44^2-2*B23*B44+B22)/B25) -> 0.04170657 | D44: GMVP
A45: =$B$23/$B$24-SQRT(($B$25*$C45^2+$B$23^2/$B$24-$B$22)/$B$24) -> 0.0075316855 | B45: =$B$23/$B$24+SQRT(($B$25*$C45^2+$B$23^2/$B$24-$B$22)/$B$24) -> 0.00935431 | C45: 0.042
A46: =$B$23/$B$24-SQRT(($B$25*$C46^2+$B$23^2/$B$24-$B$22)/$B$24) -> 0.0065182895 | B46: =$B$23/$B$24+SQRT(($B$25*$C46^2+$B$23^2/$B$24-$B$22)/$B$24) -> 0.010367706 | C46: 0.043
A47: =$B$23/$B$24-SQRT(($B$25*$C47^2+$B$23^2/$B$24-$B$22)/$B$24) -> 0.0058649873 | B47: =$B$23/$B$24+SQRT(($B$25*$C47^2+$B$23^2/$B$24-$B$22)/$B$24) -> 0.011021008 | C47: 0.044
A48: =$B$23/$B$24-SQRT(($B$25*$C48^2+$B$23^2/$B$24-$B$22)/$B$24) -> 0.0053356842 | B48: =$B$23/$B$24+SQRT(($B$25*$C48^2+$B$23^2/$B$24-$B$22)/$B$24) -> 0.011550311 | C48: 0.045
A49: =$B$23/$B$24-SQRT(($B$25*$C49^2+$B$23^2/$B$24-$B$22)/$B$24) -> 0.0048747656 | B49: =$B$23/$B$24+SQRT(($B$25*$C49^2+$B$23^2/$B$24-$B$22)/$B$24) -> 0.01201123 | C49: 0.046
A50: =$B$23/$B$24-SQRT(($B$25*$C50^2+$B$23^2/$B$24-$B$22)/$B$24) -> 0.004458429 | B50: =$B$23/$B$24+SQRT(($B$25*$C50^2+$B$23^2/$B$24-$B$22)/$B$24) -> 0.012427567 | C50: 0.047
A51: =$B$23/$B$24-SQRT(($B$25*$C51^2+$B$23^2/$B$24-$B$22)/$B$24) -> 0.004073911 | B51: =$B$23/$B$24+SQRT(($B$25*$C51^2+$B$23^2/$B$24-$B$22)/$B$24) -> 0.012812085 | C51: 0.048
A52: =$B$23/$B$24-SQRT(($B$25*$C52^2+$B$23^2/$B$24-$B$22)/$B$24) -> 0.0037134445 | B52: =$B$23/$B$24+SQRT(($B$25*$C52^2+$B$23^2/$B$24-$B$22)/$B$24) -> 0.013172551 | C52: 0.049
A53: =$B$23/$B$24-SQRT(($B$25*$C53^2+$B$23^2/$B$24-$B$22)/$B$24) -> 0.003371898 | B53: =$B$23/$B$24+SQRT(($B$25*$C53^2+$B$23^2/$B$24-$B$22)/$B$24) -> 0.013514098 | C53: 0.05
A54: =$B$23/$B$24-SQRT(($B$25*$C54^2+$B$23^2/$B$24-$B$22)/$B$24) -> 0.0030456785 | B54: =$B$23/$B$24+SQRT(($B$25*$C54^2+$B$23^2/$B$24-$B$22)/$B$24) -> 0.013840317 | C54: 0.051
A55: =$B$23/$B$24-SQRT(($B$25*$C55^2+$B$23^2/$B$24-$B$22)/$B$24) -> 0.0027321588 | B55: =$B$23/$B$24+SQRT(($B$25*$C55^2+$B$23^2/$B$24-$B$22)/$B$24) -> 0.014153837 | C55: 0.052
A56: =$B$23/$B$24-SQRT(($B$25*$C56^2+$B$23^2/$B$24-$B$22)/$B$24) -> 0.0024293523 | B56: =$B$23/$B$24+SQRT(($B$25*$C56^2+$B$23^2/$B$24-$B$22)/$B$24) -> 0.014456643 | C56: 0.053
... A183: =$B$23/$B$24-SQRT(($B$25*$C183^2+$B$23^2/$B$24-$B$22)/$B$24) -> -0.023754705 | B183: =$B$23/$B$24+SQRT(($B$25*$C183^2+$B$23^2/$B$24-$B$22)/$B$24) -> 0.0406407 | C183: 0.18

Sheet iii a
A1: Tangency portfolio equation: | E1: Capital Market Line
A8: Solving for E(RpM): | D8: risk-free rate: | E8: =i!U49 -> 0.002955
A13: A | B13: =ii!B22 -> 0.074793082 | D13: E(RpM): | E13: =(E8*B14-B13)/(E8*B15-B14) -> 0.019159786
A14: B | B14: =ii!B23 -> 4.8538655 | D14: SD(RpM): | E14: =SQRT((B15*E13^2-2*B14*E13+B13)/(B16)) -> 0.07166699
A15: C | B15: =ii!B24 -> 574.89835 | D15: Slope: | E15: =(B16*E14)/(B15*E13-B14) -> 0.22611228
A16: D | B16: =ii!B25 -> 19.438409
A19: E(Rp)- | B19: E(Rp)+ | C19: Var(Rp)^0.5 | D19: CML
C20: 0 | D20: =$E$8+$E$15*C20 -> 0.002955
C21: 0.001 | D21: =$E$8+$E$15*C21 -> 0.0031811123
C22: 0.002 | D22: =$E$8+$E$15*C22 -> 0.0034072246
C23: 0.003 | D23: =$E$8+$E$15*C23 -> 0.0036333368
C24: 0.004 | D24: =$E$8+$E$15*C24 -> 0.0038594491
C25: 0.005 | D25: =$E$8+$E$15*C25 -> 0.0040855614
C26: 0.006 | D26: =$E$8+$E$15*C26 -> 0.0043116737
C27: 0.007 | D27: =$E$8+$E$15*C27 -> 0.004537786
C28: 0.008 | D28: =$E$8+$E$15*C28 -> 0.0047638982
C29: 0.009 | D29: =$E$8+$E$15*C29 -> 0.0049900105
C30: 0.01 | D30: =$E$8+$E$15*C30 -> 0.0052161228
C31: 0.011 | D31: =$E$8+$E$15*C31 -> 0.0054422351
... C61: 0.041 | D61: =$E$8+$E$15*C61 -> 0.012225604
A62: 0.0084429978 | B62: 0.0084429978 | C62: 0.04170657 | D62: =$E$8+$E$15*C62 -> 0.012385368
A63: 0.0075316855 | B63: 0.00935431 | C63: 0.042 | D63: =$E$8+$E$15*C63 -> 0.012451716
A64: 0.0065182895 | B64: 0.010367706 | C64: 0.043 | D64: =$E$8+$E$15*C64 -> 0.012677828
A65: 0.0058649873 | B65: 0.011021008 | C65: 0.044 | D65: =$E$8+$E$15*C65 -> 0.01290394
A66: 0.0053356842 | B66: 0.011550311 | C66: 0.045 | D66: =$E$8+$E$15*C66 -> 0.013130053
A67: 0.0048747656 | B67: 0.01201123 | C67: 0.046 | D67: =$E$8+$E$15*C67 -> 0.013356165
A68: 0.004458429 | B68: 0.012427567 | C68: 0.047 | D68: =$E$8+$E$15*C68 -> 0.013582277
A69: 0.004073911 | B69: 0.012812085 | C69: 0.048 | D69: =$E$8+$E$15*C69 -> 0.013808389
A70: 0.0037134445 | B70: 0.013172551 | C70: 0.049 | D70: =$E$8+$E$15*C70 -> 0.014034502
A71: 0.003371898 | B71: 0.013514098 | C71: 0.05 | D71: =$E$8+$E$15*C71 -> 0.014260614
A72: 0.0030456785 | B72: 0.013840317 | C72: 0.051 | D72: =$E$8+$E$15*C72 -> 0.014486726
A73: 0.0027321588 | B73: 0.014153837 | C73: 0.052 | D73: =$E$8+$E$15*C73 -> 0.014712839
... A92: -0.0021226118 | B92: 0.019008607 | C92: 0.071 | D92: =$E$8+$E$15*C92 -> 0.019008972
B93: =E13 -> 0.019159786 | C93: =E14 -> 0.07166699 | D93: =$E$8+$E$15*C93 -> 0.019159786
A94: -0.0023489997 | B94: 0.019234995 | C94: 0.072 | D94: =$E$8+$E$15*C94 -> 0.019235084
A95: -0.0025738046 | B95: 0.0194598 | C95: 0.073 | D95: =$E$8+$E$15*C95 -> 0.019461196
A96: -0.0027971217 | B96: 0.019683117 | C96: 0.074 | D96: =$E$8+$E$15*C96 -> 0.019687309
A97: -0.0030190378 | B97: 0.019905033 | C97: 0.075 | D97: =$E$8+$E$15*C97 -> 0.019913421
A98: -0.0032396328 | B98: 0.020125628 | C98: 0.076 | D98: =$E$8+$E$15*C98 -> 0.020139533
A99: -0.0034589802 | B99: 0.020344976 | C99: 0.077 | D99: =$E$8+$E$15*C99 -> 0.020365646
...

Sheet iii c
A1: Equation to find weights:
B8: [E(R),1] | C8: 0.011499167 | D8: 1 | F8: V^-1 | G8: 1081.7055 | H8: -144.37771 | I8: -72.115901 | J8: -219.02291 | K8: -210.61287 | L8: -266.15124
C9: 0.0079208333 | D9: 1 | G9: -144.37771 | H9: 301.66134 | I9: 55.258628 | J9: -45.068119 | K9: -31.779875 | L9: -190.46115
C10: 0.01362 | D10: 1 | G10: -72.115901 | H10: 55.258628 | I10: 455.21172 | J10: 61.514998 | K10: -119.71855 | L10: -315.12569
C11: 0.0041933333 | D11: 1 | G11: -219.02291 | H11: -45.068119 | I11: 61.514998 | J11: 450.3451 | K11: -19.676459 | L11: -98.47205
C12: 0.013995 | D12: 1 | G12: -210.61287 | H12: -31.779875 | I12: -119.71855 | J12: -19.676459 | K12: 457.29638 | L12: -120.66568
C13: 0.0081808333 | D13: 1 | G13: -266.15124 | H13: -190.46115 | I13: -315.12569 | J13: -98.47205 | K13: -120.66568 | L13: 1301.6275
B15: K | C15: 0.074793082 | D15: 4.8538655 | F15: [E(Rp),1]' | G15: 0.019159786
C16: 4.8538655 | D16: 574.89835 | G16: 1
B18: K^-1 | C18: {=MINVERSE(C15:D16)} -> 29.575381 | D18: -0.24970487
C19: -0.24970487 | D19: 0.0038476956
A21: Calculation:
A23: 1 | B23: V^-1[E(Rp),1]' | C23: {=MMULT(G8:L13,C8:D13)} -> 4.2695994 | D23: 169.42487
C24: -0.7100676 | D24: -54.766888
C25: 1.8129063 | D25: 65.025209
C26: -1.2302321 | D26: 129.62056
C27: 1.0260448 | D27: -45.157056
C28: -0.31438531 | D28: 310.75166
A30: 2 | B30: V^-1[E(Rp),1]'K^-1 | C30: {=MMULT(_xlfn.ANCHORARRAY(C23),C18:D19)} -> 83.968812 | D30: -0.41424445
C31: -7.3249606 | D31: -0.033418977
C32: 37.380284 | D32: -0.20249434
C33: -68.751468 | D33: 0.8059354
C34: 41.621603 | D34: -0.42995899
C35: -86.894269 | D35: 1.2741814
A37: 3 | B37: W | C37: {=MMULT(_xlfn.ANCHORARRAY(C30),G15:G16)} -> 1.1945801
C38: -0.17376366
C39: 0.51370392
C40: -0.51132804
C41: 0.36750202
C42: -0.3906943

Sheet iii d 4
A1: Var(pM) | B1: =_xlfn.VAR.S(Q55:Q174) -> 0.0051361574 | C1: Var(pZ) | D1: =_xlfn.VAR.S(R55:R174) -> 2.132916e-06 | E1: COVARIANCE | F1: =_xlfn.COVARIANCE.S(Q55:Q174,R55:R174) -> -1.2925058e-05
B2: Weights
C3: Market Portfolio | D3: Risk-free
B4: CASE 1 | C4: 0 | D4: 1
B5: CASE 2 | C5: =300000/500000 -> 0.6 | D5: =1-C5 -> 0.4
B6: CASE 3 | C6: 1 | D6: 0
B8: Portfolio Variance (Treating risk-free non-zero)
B12: Standard deviations
B13: CASE 1 | C13: =(C4^2*$B$1+D4^2*$D$1+2*C4*D4*$F$1)^0.5 -> 0.0014604506
B14: CASE 2 | C14: =(C5^2*$B$1+D5^2*$D$1+2*C5*D5*$F$1)^0.5 -> 0.042931968
B15: CASE 3 | C15: =(C6^2*$B$1+D6^2*$D$1+2*C6*D6*$F$1)^0.5 -> 0.07166699
B43: Theoretical standard deviations (Assuming Var(pZ)=0 and COVARIANCE = 0)
B44: CASE 1 | C44: =(C4^2*$B$1)^0.5 -> 0
B45: CASE 2 | C45: =(C5^2*$B$1)^0.5 -> 0.043000194
B46: CASE 3 | C46: =(C6^2*$B$1)^0.5 -> 0.07166699
J51: WEIGHTED
C52: ORIGINAL | J52: {=TRANSPOSE(_xlfn.ANCHORARRAY('iii c'!C37))} -> 1.1945801 | K52: -0.17376366 | L52: 0.51370392 | M52: -0.51132804 | N52: 0.36750202 | O52: -0.3906943 | Q52: PORTFOLIO RETURN
B53: Returns | C53: Country Port | D53: Country Port | E53: Country Port | F53: Country Port | G53: Country Port | H53: Country Port | J53: =C53 -> Country Port | K53: =D53 -> Country Port | L53: =E53 -> Country Port | M53: =F53 -> Country Port | N53: =G53 -> Country Port | O53: =H53 -> Country Port | R53: US Riskfree
B54: Month | C54: Australia | D54: Hong Kong | E54: Italy | F54: Japan | G54: Norway | H54: US | J54: =C54 -> Australia | K54: =D54 -> Hong Kong | L54: =E54 -> Italy | M54: =F54 -> Japan | N54: =G54 -> Norway | O54: =H54 -> US | R54: US Riskfree
B55: 39052 | C55: 0.0359 | D55: 0.0623 | E55: 0.0272 | F55: 0.024 | G55: 0.0539 | H55: 0.0108 | J55: =J$52*C55 -> 0.042885424 | K55: =K$52*D55 -> -0.010825476 | L55: =L$52*E55 -> 0.013972746 | M55: =M$52*F55 -> -0.012271873 | N55: =N$52*G55 -> 0.019808359 | O55: =O$52*H55 -> -0.0042194984 | Q55: =SUM(J55:O55) -> 0.049349682 | R55: 0.004
B56: 39022 | C56: 0.0338 | D56: 0.0604 | E56: 0.0574 | F56: 0.0045 | G56: 0.089 | H56: 0.0237 | J56: =J$52*C56 -> 0.040376806 | K56: =K$52*D56 -> -0.010495325 | L56: =L$52*E56 -> 0.029486605 | M56: =M$52*F56 -> -0.0023009762 | N56: =N$52*G56 -> 0.03270768 | O56: =O$52*H56 -> -0.0092594548 | Q56: =SUM(J56:O56) -> 0.080515335 | R56: 0.0042
B57: 38991 | C57: 0.0865 | D57: 0.011 | E57: 0.0427 | F57: 0.0194 | G57: 0.0884 | H57: 0.0371 | J57: =J$52*C57 -> 0.10333117 | K57: =K$52*D57 -> -0.0019114002 | L57: =L$52*E57 -> 0.021935157 | M57: =M$52*F57 -> -0.0099197639 | N57: =N$52*G57 -> 0.032487179 | O57: =O$52*H57 -> -0.014494758 | Q57: =SUM(J57:O57) -> 0.13142759 | R57: 0.0041
B58: 38961 | C58: -0.0153 | D58: 0.0079 | E58: 0.0067 | F58: -0.0188 | G58: -0.0752 | H58: 0.0195 | J58: =J$52*C58 -> -0.018277075 | K58: =K$52*D58 -> -0.0013727329 | L58: =L$52*E58 -> 0.0034418162 | M58: =M$52*F58 -> 0.0096129671 | N58: =N$52*G58 -> -0.027636152 | O58: =O$52*H58 -> -0.0076185388 | Q58: =SUM(J58:O58) -> -0.041849715 | R58: 0.0041
B59: 38930 | C59: 0.0223 | D59: 0.0271 | E59: 0.0398 | F59: 0.0168 | G59: -0.0398 | H59: 0.0251 | J59: =J$52*C59 -> 0.026639135 | K59: =K$52*D59 -> -0.0047089951 | L59: =L$52*E59 -> 0.020445416 | M59: =M$52*F59 -> -0.008590311 | N59: =N$52*G59 -> -0.014626581 | O59: =O$52*H59 -> -0.0098064268 | Q59: =SUM(J59:O59) -> 0.0093522375 | R59: 0.0042
B60: 38899 | C60: 0.0174 | D60: 0.0244 | E60: 0.0103 | F60: -0.0083 | G60: 0.0406 | H60: -0.0018 | J60: =J$52*C60 -> 0.020785693 | K60: =K$52*D60 -> -0.0042398333 | L60: =L$52*E60 -> 0.0052911503 | M60: =M$52*F60 -> 0.0042440227 | N60: =N$52*G60 -> 0.014920582 | O60: =O$52*H60 -> 0.00070324973 | Q60: =SUM(J60:O60) -> 0.041704865 | R60: 0.004
B61: 38869 | C61: 0.0071 | D61: 0.0073 | E61: -0.002 | F61: -0.011 | G61: -0.029 | H61: -0.0004 | J61: =J$52*C61 -> 0.0084815184 | K61: =K$52*D61 -> -0.0012684747 | L61: =L$52*E61 -> -0.0010274078 | M61: =M$52*F61 -> 0.0056246084 | N61: =N$52*G61 -> -0.010657559 | O61: =O$52*H61 -> 0.00015627772 | Q61: =SUM(J61:O61) -> 0.0013089633 | R61: 0.004
B62: 38838 | C62: -0.0549 | D62: -0.0627 | E62: -0.0214 | F62: -0.0628 | G62: -0.0752 | H62: -0.031 | J62: =J$52*C62 -> -0.065582445 | K62: =K$52*D62 -> 0.010894981 | L62: =L$52*E62 -> -0.010993264 | M62: =M$52*F62 -> 0.032111401 | N62: =N$52*G62 -> -0.027636152 | O62: =O$52*H62 -> 0.012111523 | Q62: =SUM(J62:O62) -> -0.049093956 | R62: 0.0043
B63: 38808 | C63: 0.0933 | D63: 0.0508 | E63: 0.0415 | F63: 0.0275 | G63: 0.0982 | H63: 0.013 | J63: =J$52*C63 -> 0.11145432 | K63: =K$52*D63 -> -0.0088271938 | L63: =L$52*E63 -> 0.021318712 | M63: =M$52*F63 -> -0.014061521 | N63: =N$52*G63 -> 0.036088699 | O63: =O$52*H63 -> -0.0050790258 | Q63: =SUM(J63:O63) -> 0.14089399 | R63: 0.0036
B64: 38777 | C64: 0.0043 | D64: 0.0119 | E64: 0.0308 | F64: 0.0227 | G64: 0.1177 | H64: 0.0191 | J64: =J$52*C64 -> 0.0051366942 | K64: =K$52*D64 -> -0.0020677875 | L64: =L$52*E64 -> 0.015822081 | M64: =M$52*F64 -> -0.011607146 | N64: =N$52*G64 -> 0.043254988 | O64: =O$52*H64 -> -0.007462261 | Q64: =SUM(J64:O64) -> 0.043076568 | R64: 0.0037
B65: 38749 | C65: -0.0205 | D65: 0.0069 | E65: 0.0152 | F65: -0.0102 | G65: -0.0081 | H65: -0.0016 | J65: =J$52*C65 -> -0.024488891 | K65: =K$52*D65 -> -0.0011989692 | L65: =L$52*E65 -> 0.0078082995 | M65: =M$52*F65 -> 0.005215546 | N65: =N$52*G65 -> -0.0029767664 | O65: =O$52*H65 -> 0.00062511087 | Q65: =SUM(J65:O65) -> -0.01501567 | R65: 0.0034
B66: 38718 | C66: 0.0749 | D66: 0.058 | E66: 0.0614 | F66: 0.0434 | G66: 0.1209 | H66: 0.0401 | J66: =J$52*C66 -> 0.089474046 | K66: =K$52*D66 -> -0.010078292 | L66: =L$52*E66 -> 0.03154142 | M66: =M$52*F66 -> -0.022191637 | N66: =N$52*G66 -> 0.044430995 | O66: =O$52*H66 -> -0.015666841 | Q66: =SUM(J66:O66) -> 0.11750969 | R66: 0.0035
... B174: 35431 | C174: -0.0386 | D174: -0.0246 | E174: 0.1158 | F174: -0.1087 | G174: 0.0786 | H174: 0.0534 | J174: =J$52*C174 -> -0.04611079 | K174: =K$52*D174 -> 0.004274586 | L174: =L$52*E174 -> 0.059486913 | M174: =M$52*F174 -> 0.055581358 | N174: =N$52*G174 -> 0.028885659 | O174: =O$52*H174 -> -0.020863075 | Q174: =SUM(J174:O174) -> 0.081254651 | R174: 0.0045

Sheet iii e & iii f
K39: ********************Please note the answer for iii f is here!!! :)********************* <------------------------------------------------------------------------------
H42: Market portfolio | I42: US Riskfree
G43: Mean | H43: =Q51 -> 0.019159786 | I43: =R51 -> 0.002955
G44: SD | H44: =Q50 -> 0.07166699 | I44: =R50 -> 0.0014604506
C46: Country Port | D46: Country Port | E46: Country Port | F46: Country Port | G46: Country Port | H46: Country Port | I46: Dummy Portfolio
C47: Australia | D47: Hong Kong | E47: Italy | F47: Japan | G47: Norway | H47: US | I47: iii f
B48: E(Ri) | C48: =$R$51+C49*($Q$51-$R$51) -> 0.011499167 | D48: =$R$51+D49*($Q$51-$R$51) -> 0.0079208333 | E48: =$R$51+E49*($Q$51-$R$51) -> 0.01362 | F48: =$R$51+F49*($Q$51-$R$51) -> 0.0041933333 | G48: =$R$51+G49*($Q$51-$R$51) -> 0.013995 | H48: =$R$51+H49*($Q$51-$R$51) -> 0.0081808333 | I48: =$R$51+I49*($Q$51-$R$51) -> 0.017152684
B49: Beta | C49: =C50/$Q$50^2 -> 0.52726191 | D49: =D50/$Q$50^2 -> 0.30644238 | E49: =E50/$Q$50^2 -> 0.65813888 | F49: =F50/$Q$50^2 -> 0.076417751 | G49: =G50/$Q$50^2 -> 0.68128019 | H49: =H50/$Q$50^2 -> 0.32248702 | I49: =I50/$Q$50^2 -> 0.87614137
B50: Cov | C50: =_xlfn.COVARIANCE.S(C55:C174,$Q$55:$Q$174) -> 0.0027081002 | D50: =_xlfn.COVARIANCE.S(D55:D174,$Q$55:$Q$174) -> 0.0015739363 | E50: =_xlfn.COVARIANCE.S(E55:E174,$Q$55:$Q$174) -> 0.0033803049 | F50: =_xlfn.COVARIANCE.S(F55:F174,$Q$55:$Q$174) -> 0.0003924936 | G50: =_xlfn.COVARIANCE.S(G55:G174,$Q$55:$Q$174) -> 0.0034991623 | H50: =_xlfn.COVARIANCE.S(H55:H174,$Q$55:$Q$174) -> 0.0016563441 | I50: 0.0045 | P50: SD | Q50: =_xlfn.VAR.S(Q55:Q174)^0.5 -> 0.07166699 | R50: =_xlfn.VAR.S(R55:R174)^0.5 -> 0.0014604506
B51: Mean | C51: =AVERAGE(C55:C174) -> 0.011499167 | D51: =AVERAGE(D55:D174) -> 0.0079208333 | E51: =AVERAGE(E55:E174) -> 0.01362 | F51: =AVERAGE(F55:F174) -> 0.0041933333 | G51: =AVERAGE(G55:G174) -> 0.013995 | H51: =AVERAGE(H55:H174) -> 0.0081808333 | J51: WEIGHTED | P51: Mean | Q51: =AVERAGE(Q55:Q174) -> 0.019159786 | R51: =AVERAGE(R55:R174) -> 0.002955
C52: ORIGINAL | J52: {=TRANSPOSE(_xlfn.ANCHORARRAY('iii c'!C37))} -> 1.1945801 | K52: -0.17376366 | L52: 0.51370392 | M52: -0.51132804 | N52: 0.36750202 | O52: -0.3906943 | Q52: PORTFOLIO RETURN | T52: SML
B53: Returns | C53: Country Port | D53: Country Port | E53: Country Port | F53: Country Port | G53: Country Port | H53: Country Port | J53: =C53 -> Country Port | K53: =D53 -> Country Port | L53: =E53 -> Country Port | M53: =F53 -> Country Port | N53: =G53 -> Country Port | O53: =H53 -> Country Port | R53: US Riskfree | T53: E(Ri) | U53: Beta
B54: Month | C54: Australia | D54: Hong Kong | E54: Italy | F54: Japan | G54: Norway | H54: US | J54: =C54 -> Australia | K54: =D54 -> Hong Kong | L54: =E54 -> Italy | M54: =F54 -> Japan | N54: =G54 -> Norway | O54: =H54 -> US | R54: US Riskfree
B55: 39052 | C55: 0.0359 | D55: 0.0623 | E55: 0.0272 | F55: 0.024 | G55: 0.0539 | H55: 0.0108 | J55: =J$52*C55 -> 0.042885424 | K55: =K$52*D55 -> -0.010825476 | L55: =L$52*E55 -> 0.013972746 | M55: =M$52*F55 -> -0.012271873 | N55: =N$52*G55 -> 0.019808359 | O55: =O$52*H55 -> -0.0042194984 | Q55: =SUM(J55:O55) -> 0.049349682 | R55: 0.004
B56: 39022 | C56: 0.0338 | D56: 0.0604 | E56: 0.0574 | F56: 0.0045 | G56: 0.089 | H56: 0.0237 | J56: =J$52*C56 -> 0.040376806 | K56: =K$52*D56 -> -0.010495325 | L56: =L$52*E56 -> 0.029486605 | M56: =M$52*F56 -> -0.0023009762 | N56: =N$52*G56 -> 0.03270768 | O56: =O$52*H56 -> -0.0092594548 | Q56: =SUM(J56:O56) -> 0.080515335 | R56: 0.0042 | T56: =$I$43+U56*($H$43-$I$43) -> 0.002955 | U56: 0
B57: 38991 | C57: 0.0865 | D57: 0.011 | E57: 0.0427 | F57: 0.0194 | G57: 0.0884 | H57: 0.0371 | J57: =J$52*C57 -> 0.10333117 | K57: =K$52*D57 -> -0.0019114002 | L57: =L$52*E57 -> 0.021935157 | M57: =M$52*F57 -> -0.0099197639 | N57: =N$52*G57 -> 0.032487179 | O57: =O$52*H57 -> -0.014494758 | Q57: =SUM(J57:O57) -> 0.13142759 | R57: 0.0041 | T57: =$I$43+U57*($H$43-$I$43) -> 0.0031170479 | U57: 0.01
B58: 38961 | C58: -0.0153 | D58: 0.0079 | E58: 0.0067 | F58: -0.0188 | G58: -0.0752 | H58: 0.0195 | J58: =J$52*C58 -> -0.018277075 | K58: =K$52*D58 -> -0.0013727329 | L58: =L$52*E58 -> 0.0034418162 | M58: =M$52*F58 -> 0.0096129671 | N58: =N$52*G58 -> -0.027636152 | O58: =O$52*H58 -> -0.0076185388 | Q58: =SUM(J58:O58) -> -0.041849715 | R58: 0.0041 | T58: =$I$43+U58*($H$43-$I$43) -> 0.0032790957 | U58: 0.02
B59: 38930 | C59: 0.0223 | D59: 0.0271 | E59: 0.0398 | F59: 0.0168 | G59: -0.0398 | H59: 0.0251 | J59: =J$52*C59 -> 0.026639135 | K59: =K$52*D59 -> -0.0047089951 | L59: =L$52*E59 -> 0.020445416 | M59: =M$52*F59 -> -0.008590311 | N59: =N$52*G59 -> -0.014626581 | O59: =O$52*H59 -> -0.0098064268 | Q59: =SUM(J59:O59) -> 0.0093522375 | R59: 0.0042 | T59: =$I$43+U59*($H$43-$I$43) -> 0.0034411436 | U59: 0.03
B60: 38899 | C60: 0.0174 | D60: 0.0244 | E60: 0.0103 | F60: -0.0083 | G60: 0.0406 | H60: -0.0018 | J60: =J$52*C60 -> 0.020785693 | K60: =K$52*D60 -> -0.0042398333 | L60: =L$52*E60 -> 0.0052911503 | M60: =M$52*F60 -> 0.0042440227 | N60: =N$52*G60 -> 0.014920582 | O60: =O$52*H60 -> 0.00070324973 | Q60: =SUM(J60:O60) -> 0.041704865 | R60: 0.004 | T60: =$I$43+U60*($H$43-$I$43) -> 0.0036031915 | U60: 0.04
B61: 38869 | C61: 0.0071 | D61: 0.0073 | E61: -0.002 | F61: -0.011 | G61: -0.029 | H61: -0.0004 | J61: =J$52*C61 -> 0.0084815184 | K61: =K$52*D61 -> -0.0012684747 | L61: =L$52*E61 -> -0.0010274078 | M61: =M$52*F61 -> 0.0056246084 | N61: =N$52*G61 -> -0.010657559 | O61: =O$52*H61 -> 0.00015627772 | Q61: =SUM(J61:O61) -> 0.0013089633 | R61: 0.004 | T61: =$I$43+U61*($H$43-$I$43) -> 0.0037652393 | U61: 0.05
B62: 38838 | C62: -0.0549 | D62: -0.0627 | E62: -0.0214 | F62: -0.0628 | G62: -0.0752 | H62: -0.031 | J62: =J$52*C62 -> -0.065582445 | K62: =K$52*D62 -> 0.010894981 | L62: =L$52*E62 -> -0.010993264 | M62: =M$52*F62 -> 0.032111401 | N62: =N$52*G62 -> -0.027636152 | O62: =O$52*H62 -> 0.012111523 | Q62: =SUM(J62:O62) -> -0.049093956 | R62: 0.0043 | T62: =$I$43+U62*($H$43-$I$43) -> 0.0039272872 | U62: 0.06
B63: 38808 | C63: 0.0933 | D63: 0.0508 | E63: 0.0415 | F63: 0.0275 | G63: 0.0982 | H63: 0.013 | J63: =J$52*C63 -> 0.11145432 | K63: =K$52*D63 -> -0.0088271938 | L63: =L$52*E63 -> 0.021318712 | M63: =M$52*F63 -> -0.014061521 | N63: =N$52*G63 -> 0.036088699 | O63: =O$52*H63 -> -0.0050790258 | Q63: =SUM(J63:O63) -> 0.14089399 | R63: 0.0036 | T63: =$I$43+U63*($H$43-$I$43) -> 0.0040893351 | U63: 0.07
B64: 38777 | C64: 0.0043 | D64: 0.0119 | E64: 0.0308 | F64: 0.0227 | G64: 0.1177 | H64: 0.0191 | J64: =J$52*C64 -> 0.0051366942 | K64: =K$52*D64 -> -0.0020677875 | L64: =L$52*E64 -> 0.015822081 | M64: =M$52*F64 -> -0.011607146 | N64: =N$52*G64 -> 0.043254988 | O64: =O$52*H64 -> -0.007462261 | Q64: =SUM(J64:O64) -> 0.043076568 | R64: 0.0037 | T64: =$I$43+U64*($H$43-$I$43) -> 0.0042513829 | U64: 0.08
B65: 38749 | C65: -0.0205 | D65: 0.0069 | E65: 0.0152 | F65: -0.0102 | G65: -0.0081 | H65: -0.0016 | J65: =J$52*C65 -> -0.024488891 | K65: =K$52*D65 -> -0.0011989692 | L65: =L$52*E65 -> 0.0078082995 | M65: =M$52*F65 -> 0.005215546 | N65: =N$52*G65 -> -0.0029767664 | O65: =O$52*H65 -> 0.00062511087 | Q65: =SUM(J65:O65) -> -0.01501567 | R65: 0.0034 | T65: =$I$43+U65*($H$43-$I$43) -> 0.0044134308 | U65: 0.09
B66: 38718 | C66: 0.0749 | D66: 0.058 | E66: 0.0614 | F66: 0.0434 | G66: 0.1209 | H66: 0.0401 | J66: =J$52*C66 -> 0.089474046 | K66: =K$52*D66 -> -0.010078292 | L66: =L$52*E66 -> 0.03154142 | M66: =M$52*F66 -> -0.022191637 | N66: =N$52*G66 -> 0.044430995 | O66: =O$52*H66 -> -0.015666841 | Q66: =SUM(J66:O66) -> 0.11750969 | R66: 0.0035 | T66: =$I$43+U66*($H$43-$I$43) -> 0.0045754786 | U66: 0.1
B67: 38687 | C67: 0.0247 | D67: 0.012 | E67: 0.0439 | F67: 0.0891 | G67: 0.0459 | H67: 0.0035 | J67: =J$52*C67 -> 0.029506127 | K67: =K$52*D67 -> -0.0020851639 | L67: =L$52*E67 -> 0.022551602 | M67: =M$52*F67 -> -0.045559328 | N67: =N$52*G67 -> 0.016868343 | O67: =O$52*H67 -> -0.00136743 | Q67: =SUM(J67:O67) -> 0.01991415 | R67: 0.0032 | T67: =$I$43+U67*($H$43-$I$43) -> 0.0047375265 | U67: 0.11
... B174: 35431 | C174: -0.0386 | D174: -0.0246 | E174: 0.1158 | F174: -0.1087 | G174: 0.0786 | H174: 0.0534 | J174: =J$52*C174 -> -0.04611079 | K174: =K$52*D174 -> 0.004274586 | L174: =L$52*E174 -> 0.059486913 | M174: =M$52*F174 -> 0.055581358 | N174: =N$52*G174 -> 0.028885659 | O174: =O$52*H174 -> -0.020863075 | Q174: =SUM(J174:O174) -> 0.081254651 | R174: 0.0045 | T174: =$I$43+U174*($H$43-$I$43) -> 0.022076648 | U174: 1.18
